Workbook

Sheet Настройки
A2: Концепции критерии и участники
A4: Замените названия и критерии перед оцениванием. Цветные ячейки доступны для ввода.
A6: Код эксперта | B6: ФИО
A7: Э1 | B7: Кветкин Дмитрий Евгеньевич
A8: Э2 | B8: Колбасин Николай Владимирович
A9: Э3 | B9: Добросоцкий Михаил Сергеевич
A10: Э4 | B10: Катаев Максим Игоревич
A13: Код проекта | B13: Название | C13: Статус
A14: A1 | B14: Детейлинг-центр | C14: Предложение
A15: A2 | B15: Планировщик покупок | C15: Предложение
A16: A3 | B16: Концепция 3 | C16: Заменить
A17: A4 | B17: Концепция 4 | C17: Заменить
A20: Код критерия | B20: Название | C20: Направление | D20: Что оцениваем
A21: K1 | B21: Практическая полезность | C21: MAX | D21: Польза приложения для выбранных пользователей
A22: K2 | B22: Простота реализации | C22: MAX | D22: Чем проще минимальная версия, тем выше оценка
A23: K3 | B23: Удобство оценки и планирования | C23: MAX | D23: Понятность сценариев, данных и задач для следующих фаз
A24: K4 | B24: Интерес команды | C24: MAX | D24: Интерес и знакомство участников с предметной областью
A27: MAX: больше лучше. MIN: меньше лучше. В МАИ всегда сравнивается предпочтительность.
A29: Параметр | B29: Значение
A30: Максимум шкалы TOPSIS | B30: 9
A31: Порог согласованности CR | B31: 0.1
A32: RI для матрицы 4 × 4 | B32: 0.9
A35: 4 эксперта имеют одинаковый вес. TOPSIS: тройка MIN / MEDIAN / MAX.
A37: Это адаптация трёх экспертных оценок из задания для команды из 4 человек.
A40: Методические источники
A41: Chen C.-T. 2000 | B41: https://doi.org/10.1016/S0165-0114(97)00377-1
A42: Saaty T. L. 2008 | B42: https://doi.org/10.1504/IJSSCI.2008.017590
A43: Xu Z. 2000: коллективный МАИ | B43: https://doi.org/10.1016/S0377-2217(99)00082-X

Sheet Концепции
A1: Концепции проектов
A2: Согласуйте 4 концепции и критерии, затем каждый независимо оценивает все проекты.
A3: Названия связаны с «Настройками». Заполняйте жёлтые ячейки; требуется 10–15 сценариев на концепцию.
A5: A1: описание концепции
A6: Код | B6: A1
A7: Название для рейтингов | B7: ='Настройки'!B14 -> Детейлинг-центр
A8: Полное название | B8: Система записи и управления заказами детейлинг-центра
A9: Предложил | B9: ='Настройки'!B7 -> Кветкин Дмитрий Евгеньевич
A10: Назначение | B10: Запись клиентов на услуги, распределение заказов между мастерами и отслеживание выполнения.
A11: Пользователи | B11: Клиент, администратор, мастер.
A12: Минимальная версия | B12: Веб-приложение одного центра: учётные записи, автомобили, каталог услуг, расписание, заказы, назначение мастеров и отчёт.
A13: За пределами проекта | B13: Онлайн-оплата, складской учёт, закупки, бухгалтерские интеграции, SMS и мобильное приложение.
A14: Упрощения и правила | B14: Один заказ - один автомобиль и одна услуга фиксированной длительности; работы выполняет один мастер. Пересечения времени запрещены.
A15: Состояние описания | B15: Предложена для сравнения. Подготовлено 12 сценариев; выбор проекта и критериев согласует команда.
A16: № | B16: Пользователь | C16: Действие | D16: Результат системы
A17: 1 | B17: Пользователь | C17: Регистрируется и входит в личный кабинет. | D17: Сохраняет учётную запись и предоставляет доступ по роли.
A18: 2 | B18: Клиент | C18: Добавляет марку, модель и госномер автомобиля. | D18: Сохраняет автомобиль в профиле клиента.
A19: 3 | B19: Клиент | C19: Просматривает каталог услуг. | D19: Показывает услуги, цены и продолжительность работ.
A20: 4 | B20: Клиент | C20: Выбирает услугу и дату. | D20: Показывает свободное время с учётом длительности услуги и занятости мастеров.
A21: 5 | B21: Клиент | C21: Создаёт запись на выбранное время. | D21: Сохраняет заказ и резервирует время; повторная запись на занятый интервал запрещена.
A22: 6 | B22: Клиент | C22: Переносит запись на свободное время. | D22: Резервирует новый интервал и освобождает прежний.
A23: 7 | B23: Клиент | C23: Отменяет запись до начала работ. | D23: Меняет статус на «Отменён» и освобождает время.
A24: 8 | B24: Администратор | C24: Подтверждает запись или отклоняет с указанием причины. | D24: Сохраняет решение; при отклонении освобождает время.
A25: 9 | B25: Администратор | C25: Назначает свободного мастера на заказ. | D25: Сохраняет назначение и проверяет отсутствие пересечений его заказов.
A26: 10 | B26: Мастер | C26: Меняет статус своего заказа на «В работе» или «Завершён». | D26: Сохраняет статус; клиент и администратор видят его в заказе.
A27: 11 | B27: Администратор | C27: Добавляет услуги или изменяет цены. | D27: Обновляет каталог; стоимость уже созданных заказов сохраняется.
A28: 12 | B28: Администратор | C28: Выбирает период отчёта. | D28: Показывает завершённые заказы и их общую стоимость; это стоимость заказов, а не подтверждение оплаты.
A29: 13
A30: 14
A31: 15
A33: A2: описание концепции
A34: Код | B34: A2
A35: Название для рейтингов | B35: ='Настройки'!B15 -> Планировщик покупок
A36: Полное название | B36: Приложение для автоматизированного формирования и оптимизации списка покупок на основе недельного меню.
A37: Предложил | B37: ='Настройки'!B9 -> Добросоцкий Михаил Сергеевич
A38: Назначение | B38: Приложение, которое автоматически преобразует составленное пользователем меню на неделю в оптимизированный список покупок с учётом необходимых объёмов ингредиентов, стандартных размеров упаковок, имеющихся дома продуктов и возможности использовать один продукт в нескольких блюдах. Система суммирует одинаковые ингредиенты, рассчитывает необходимое количество упаковок и формирует единый список покупок, помогая сократить время планирования и уменьшить количество излишне приобретённых продуктов.
A39: Пользователи | B39: Спортсмены которым необходимо составлять план питания под свои КБЖУ, студенты и рабочие которым необходимо меньше задуматься о том что купить, семьи которым удобнее контролировать большой объем потребления пищи
A40: Минимальная версия | B40: Возможность выбирать блюда из каталога или создавать собственные рецепты, указывать количество порций и составлять меню; возможность рассчета остатков продуктов; приложение должно суммировать одинаковые ингредиенты из всех блюд; округлять необходимое количество до целых упаковок; формировать итоговый список покупок; редактирование списка; отметка купленных продуктов.
A41: За пределами проекта | B41: Интеграция с реальными онлайн-магазинами и автоматическое оформление заказов; автоматическое распознавание продуктов по фотографиям; генерация рецептов с помощью искусственного интеллекта; список любимых блюд
A42: Упрощения и правила | B42: Меню планируется на одну неделю; пользователь самостоятельно выбирает блюда и задаёт количество порций; каждый рецепт содержит заранее определённый список ингредиентов с количеством и единицами измерения; одинаковые продукты из разных блюд объединяются в одну позицию списка покупок; количество приобретаемых упаковок должно быть целым и достаточным для приготовления; система не учитывает фактические остатки продуктов после окончания недели и изменение сроков их хранения
...

Sheet Эксперт 1
A2: Индивидуальные оценки эксперта 1
A4: Участник | B4: ='Настройки'!B7 -> Кветкин Дмитрий Евгеньевич
A5: Заполняйте только жёлтые ячейки. Не копируйте оценки других участников.
A7: TOPSIS: важность критерия | B7: Оценка 1–9
A8: ='Настройки'!B21 -> Практическая полезность
A9: ='Настройки'!B22 -> Простота реализации
A10: ='Настройки'!B23 -> Удобство оценки и планирования
A11: ='Настройки'!B24 -> Интерес команды
A13: TOPSIS: оценка проекта | B13: ='Настройки'!B21 -> Практическая полезность | C13: ='Настройки'!B22 -> Простота реализации | D13: ='Настройки'!B23 -> Удобство оценки и планирования | E13: ='Настройки'!B24 -> Интерес команды
A14: ='Настройки'!B14 -> Детейлинг-центр | B14: 8 | C14: 7 | D14: 9 | E14: 9
A15: ='Настройки'!B15 -> Планировщик покупок
A16: ='Настройки'!B16 -> Концепция 3
A17: ='Настройки'!B17 -> Концепция 4
A19: Оценок TOPSIS заполнено / 20 | B19: =COUNT(B8:B11,B14:E17) -> 4
A21: МАИ: 1 равноценно; 3 умеренно; 5 сильно; 7 очень сильно; 9 предельно.
A22: Если строка уступает столбцу, вводите =1/3, =1/5 и т. п.
A24: МАИ: сравнение важности критериев
A25: Строка предпочтительнее столбца | B25: ='Настройки'!B21 -> Практическая полезность | C25: ='Настройки'!B22 -> Простота реализации | D25: ='Настройки'!B23 -> Удобство оценки и планирования | E25: ='Настройки'!B24 -> Интерес команды
A26: ='Настройки'!B21 -> Практическая полезность | B26: 1
A27: ='Настройки'!B22 -> Простота реализации | B27: =IF(COUNT(C26)=0,"",1/C26) | C27: 1
A28: ='Настройки'!B23 -> Удобство оценки и планирования | B28: =IF(COUNT(D26)=0,"",1/D26) | C28: =IF(COUNT(D27)=0,"",1/D27) | D28: 1
A29: ='Настройки'!B24 -> Интерес команды | B29: =IF(COUNT(E26)=0,"",1/E26) | C29: =IF(COUNT(E27)=0,"",1/E27) | D29: =IF(COUNT(E28)=0,"",1/E28) | E29: 1
A31: CR: допустимо не более 0,10 | B31: =IF(COUNT('МАИ'!B98)=0,"",'МАИ'!B98) | C31: =IF(COUNT(B31)=0,"Нет оценок",IF(B31<='Настройки'!$B$31,"Согласовано","Пересмотреть")) -> Нет оценок
A36: МАИ: проекты по критерию K1 | B36: ='Настройки'!B21 -> Практическая полезность
A37: Строка предпочтительнее столбца | B37: ='Настройки'!B14 -> Детейлинг-центр | C37: ='Настройки'!B15 -> Планировщик покупок | D37: ='Настройки'!B16 -> Концепция 3 | E37: ='Настройки'!B17 -> Концепция 4
A38: ='Настройки'!B14 -> Детейлинг-центр | B38: 1
A39: ='Настройки'!B15 -> Планировщик покупок | B39: =IF(COUNT(C38)=0,"",1/C38) | C39: 1
A40: ='Настройки'!B16 -> Концепция 3 | B40: =IF(COUNT(D38)=0,"",1/D38) | C40: =IF(COUNT(D39)=0,"",1/D39) | D40: 1
A41: ='Настройки'!B17 -> Концепция 4 | B41: =IF(COUNT(E38)=0,"",1/E38) | C41: =IF(COUNT(E39)=0,"",1/E39) | D41: =IF(COUNT(E40)=0,"",1/E40) | E41: 1
A43: CR: допустимо не более 0,10 | B43: =IF(COUNT('МАИ'!B112)=0,"",'МАИ'!B112) | C43: =IF(COUNT(B43)=0,"Нет оценок",IF(B43<='Настройки'!$B$31,"Согласовано","Пересмотреть")) -> Нет оценок
A48: МАИ: проекты по критерию K2 | B48: ='Настройки'!B22 -> Простота реализации
A49: Строка предпочтительнее столбца | B49: ='Настройки'!B14 -> Детейлинг-центр | C49: ='Настройки'!B15 -> Планировщик покупок | D49: ='Настройки'!B16 -> Концепция 3 | E49: ='Настройки'!B17 -> Концепция 4
A50: ='Настройки'!B14 -> Детейлинг-центр | B50: 1
A51: ='Настройки'!B15 -> Планировщик покупок | B51: =IF(COUNT(C50)=0,"",1/C50) | C51: 1
A52: ='Настройки'!B16 -> Концепция 3 | B52: =IF(COUNT(D50)=0,"",1/D50) | C52: =IF(COUNT(D51)=0,"",1/D51) | D52: 1
A53: ='Настройки'!B17 -> Концепция 4 | B53: =IF(COUNT(E50)=0,"",1/E50) | C53: =IF(COUNT(E51)=0,"",1/E51) | D53: =IF(COUNT(E52)=0,"",1/E52) | E53: 1
A55: CR: допустимо не более 0,10 | B55: =IF(COUNT('МАИ'!B126)=0,"",'МАИ'!B126) | C55: =IF(COUNT(B55)=0,"Нет оценок",IF(B55<='Настройки'!$B$31,"Согласовано","Пересмотреть")) -> Нет оценок
A60: МАИ: проекты по критерию K3 | B60: ='Настройки'!B23 -> Удобство оценки и планирования
A61: Строка предпочтительнее столбца | B61: ='Настройки'!B14 -> Детейлинг-центр | C61: ='Настройки'!B15 -> Планировщик покупок | D61: ='Настройки'!B16 -> Концепция 3 | E61: ='Настройки'!B17 -> Концепция 4
A62: ='Настройки'!B14 -> Детейлинг-центр | B62: 1
...

Sheet Эксперт 2
A2: Индивидуальные оценки эксперта 2
A4: Участник | B4: ='Настройки'!B8 -> Колбасин Николай Владимирович
A5: Заполняйте только жёлтые ячейки. Не копируйте оценки других участников.
A7: TOPSIS: важность критерия | B7: Оценка 1–9
A8: ='Настройки'!B21 -> Практическая полезность
A9: ='Настройки'!B22 -> Простота реализации
A10: ='Настройки'!B23 -> Удобство оценки и планирования
A11: ='Настройки'!B24 -> Интерес команды
A13: TOPSIS: оценка проекта | B13: ='Настройки'!B21 -> Практическая полезность | C13: ='Настройки'!B22 -> Простота реализации | D13: ='Настройки'!B23 -> Удобство оценки и планирования | E13: ='Настройки'!B24 -> Интерес команды
A14: ='Настройки'!B14 -> Детейлинг-центр
A15: ='Настройки'!B15 -> Планировщик покупок
A16: ='Настройки'!B16 -> Концепция 3
A17: ='Настройки'!B17 -> Концепция 4
A19: Оценок TOPSIS заполнено / 20 | B19: =COUNT(B8:B11,B14:E17) -> 0
A21: МАИ: 1 равноценно; 3 умеренно; 5 сильно; 7 очень сильно; 9 предельно.
A22: Если строка уступает столбцу, вводите =1/3, =1/5 и т. п.
A24: МАИ: сравнение важности критериев
A25: Строка предпочтительнее столбца | B25: ='Настройки'!B21 -> Практическая полезность | C25: ='Настройки'!B22 -> Простота реализации | D25: ='Настройки'!B23 -> Удобство оценки и планирования | E25: ='Настройки'!B24 -> Интерес команды
A26: ='Настройки'!B21 -> Практическая полезность | B26: 1
A27: ='Настройки'!B22 -> Простота реализации | B27: =IF(COUNT(C26)=0,"",1/C26) | C27: 1
A28: ='Настройки'!B23 -> Удобство оценки и планирования | B28: =IF(COUNT(D26)=0,"",1/D26) | C28: =IF(COUNT(D27)=0,"",1/D27) | D28: 1
A29: ='Настройки'!B24 -> Интерес команды | B29: =IF(COUNT(E26)=0,"",1/E26) | C29: =IF(COUNT(E27)=0,"",1/E27) | D29: =IF(COUNT(E28)=0,"",1/E28) | E29: 1
A31: CR: допустимо не более 0,10 | B31: =IF(COUNT('МАИ'!B168)=0,"",'МАИ'!B168) | C31: =IF(COUNT(B31)=0,"Нет оценок",IF(B31<='Настройки'!$B$31,"Согласовано","Пересмотреть")) -> Нет оценок
A36: МАИ: проекты по критерию K1 | B36: ='Настройки'!B21 -> Практическая полезность
A37: Строка предпочтительнее столбца | B37: ='Настройки'!B14 -> Детейлинг-центр | C37: ='Настройки'!B15 -> Планировщик покупок | D37: ='Настройки'!B16 -> Концепция 3 | E37: ='Настройки'!B17 -> Концепция 4
A38: ='Настройки'!B14 -> Детейлинг-центр | B38: 1
A39: ='Настройки'!B15 -> Планировщик покупок | B39: =IF(COUNT(C38)=0,"",1/C38) | C39: 1
A40: ='Настройки'!B16 -> Концепция 3 | B40: =IF(COUNT(D38)=0,"",1/D38) | C40: =IF(COUNT(D39)=0,"",1/D39) | D40: 1
A41: ='Настройки'!B17 -> Концепция 4 | B41: =IF(COUNT(E38)=0,"",1/E38) | C41: =IF(COUNT(E39)=0,"",1/E39) | D41: =IF(COUNT(E40)=0,"",1/E40) | E41: 1
A43: CR: допустимо не более 0,10 | B43: =IF(COUNT('МАИ'!B182)=0,"",'МАИ'!B182) | C43: =IF(COUNT(B43)=0,"Нет оценок",IF(B43<='Настройки'!$B$31,"Согласовано","Пересмотреть")) -> Нет оценок
A48: МАИ: проекты по критерию K2 | B48: ='Настройки'!B22 -> Простота реализации
A49: Строка предпочтительнее столбца | B49: ='Настройки'!B14 -> Детейлинг-центр | C49: ='Настройки'!B15 -> Планировщик покупок | D49: ='Настройки'!B16 -> Концепция 3 | E49: ='Настройки'!B17 -> Концепция 4
A50: ='Настройки'!B14 -> Детейлинг-центр | B50: 1
A51: ='Настройки'!B15 -> Планировщик покупок | B51: =IF(COUNT(C50)=0,"",1/C50) | C51: 1
A52: ='Настройки'!B16 -> Концепция 3 | B52: =IF(COUNT(D50)=0,"",1/D50) | C52: =IF(COUNT(D51)=0,"",1/D51) | D52: 1
A53: ='Настройки'!B17 -> Концепция 4 | B53: =IF(COUNT(E50)=0,"",1/E50) | C53: =IF(COUNT(E51)=0,"",1/E51) | D53: =IF(COUNT(E52)=0,"",1/E52) | E53: 1
A55: CR: допустимо не более 0,10 | B55: =IF(COUNT('МАИ'!B196)=0,"",'МАИ'!B196) | C55: =IF(COUNT(B55)=0,"Нет оценок",IF(B55<='Настройки'!$B$31,"Согласовано","Пересмотреть")) -> Нет оценок
A60: МАИ: проекты по критерию K3 | B60: ='Настройки'!B23 -> Удобство оценки и планирования
A61: Строка предпочтительнее столбца | B61: ='Настройки'!B14 -> Детейлинг-центр | C61: ='Настройки'!B15 -> Планировщик покупок | D61: ='Настройки'!B16 -> Концепция 3 | E61: ='Настройки'!B17 -> Концепция 4
A62: ='Настройки'!B14 -> Детейлинг-центр | B62: 1
...

Sheet Эксперт 3
A2: Индивидуальные оценки эксперта 3
A4: Участник | B4: ='Настройки'!B9 -> Добросоцкий Михаил Сергеевич
A5: Заполняйте только жёлтые ячейки. Не копируйте оценки других участников.
A7: TOPSIS: важность критерия | B7: Оценка 1–9
A8: ='Настройки'!B21 -> Практическая полезность
A9: ='Настройки'!B22 -> Простота реализации
A10: ='Настройки'!B23 -> Удобство оценки и планирования
A11: ='Настройки'!B24 -> Интерес команды
A13: TOPSIS: оценка проекта | B13: ='Настройки'!B21 -> Практическая полезность | C13: ='Настройки'!B22 -> Простота реализации | D13: ='Настройки'!B23 -> Удобство оценки и планирования | E13: ='Настройки'!B24 -> Интерес команды
A14: ='Настройки'!B14 -> Детейлинг-центр
A15: ='Настройки'!B15 -> Планировщик покупок
A16: ='Настройки'!B16 -> Концепция 3
A17: ='Настройки'!B17 -> Концепция 4
A19: Оценок TOPSIS заполнено / 20 | B19: =COUNT(B8:B11,B14:E17) -> 0
A21: МАИ: 1 равноценно; 3 умеренно; 5 сильно; 7 очень сильно; 9 предельно.
A22: Если строка уступает столбцу, вводите =1/3, =1/5 и т. п.
A24: МАИ: сравнение важности критериев
A25: Строка предпочтительнее столбца | B25: ='Настройки'!B21 -> Практическая полезность | C25: ='Настройки'!B22 -> Простота реализации | D25: ='Настройки'!B23 -> Удобство оценки и планирования | E25: ='Настройки'!B24 -> Интерес команды
A26: ='Настройки'!B21 -> Практическая полезность | B26: 1
A27: ='Настройки'!B22 -> Простота реализации | B27: =IF(COUNT(C26)=0,"",1/C26) | C27: 1
A28: ='Настройки'!B23 -> Удобство оценки и планирования | B28: =IF(COUNT(D26)=0,"",1/D26) | C28: =IF(COUNT(D27)=0,"",1/D27) | D28: 1
A29: ='Настройки'!B24 -> Интерес команды | B29: =IF(COUNT(E26)=0,"",1/E26) | C29: =IF(COUNT(E27)=0,"",1/E27) | D29: =IF(COUNT(E28)=0,"",1/E28) | E29: 1
A31: CR: допустимо не более 0,10 | B31: =IF(COUNT('МАИ'!B238)=0,"",'МАИ'!B238) | C31: =IF(COUNT(B31)=0,"Нет оценок",IF(B31<='Настройки'!$B$31,"Согласовано","Пересмотреть")) -> Нет оценок
A36: МАИ: проекты по критерию K1 | B36: ='Настройки'!B21 -> Практическая полезность
A37: Строка предпочтительнее столбца | B37: ='Настройки'!B14 -> Детейлинг-центр | C37: ='Настройки'!B15 -> Планировщик покупок | D37: ='Настройки'!B16 -> Концепция 3 | E37: ='Настройки'!B17 -> Концепция 4
A38: ='Настройки'!B14 -> Детейлинг-центр | B38: 1
A39: ='Настройки'!B15 -> Планировщик покупок | B39: =IF(COUNT(C38)=0,"",1/C38) | C39: 1
A40: ='Настройки'!B16 -> Концепция 3 | B40: =IF(COUNT(D38)=0,"",1/D38) | C40: =IF(COUNT(D39)=0,"",1/D39) | D40: 1
A41: ='Настройки'!B17 -> Концепция 4 | B41: =IF(COUNT(E38)=0,"",1/E38) | C41: =IF(COUNT(E39)=0,"",1/E39) | D41: =IF(COUNT(E40)=0,"",1/E40) | E41: 1
A43: CR: допустимо не более 0,10 | B43: =IF(COUNT('МАИ'!B252)=0,"",'МАИ'!B252) | C43: =IF(COUNT(B43)=0,"Нет оценок",IF(B43<='Настройки'!$B$31,"Согласовано","Пересмотреть")) -> Нет оценок
A48: МАИ: проекты по критерию K2 | B48: ='Настройки'!B22 -> Простота реализации
A49: Строка предпочтительнее столбца | B49: ='Настройки'!B14 -> Детейлинг-центр | C49: ='Настройки'!B15 -> Планировщик покупок | D49: ='Настройки'!B16 -> Концепция 3 | E49: ='Настройки'!B17 -> Концепция 4
A50: ='Настройки'!B14 -> Детейлинг-центр | B50: 1
A51: ='Настройки'!B15 -> Планировщик покупок | B51: =IF(COUNT(C50)=0,"",1/C50) | C51: 1
A52: ='Настройки'!B16 -> Концепция 3 | B52: =IF(COUNT(D50)=0,"",1/D50) | C52: =IF(COUNT(D51)=0,"",1/D51) | D52: 1
A53: ='Настройки'!B17 -> Концепция 4 | B53: =IF(COUNT(E50)=0,"",1/E50) | C53: =IF(COUNT(E51)=0,"",1/E51) | D53: =IF(COUNT(E52)=0,"",1/E52) | E53: 1
A55: CR: допустимо не более 0,10 | B55: =IF(COUNT('МАИ'!B266)=0,"",'МАИ'!B266) | C55: =IF(COUNT(B55)=0,"Нет оценок",IF(B55<='Настройки'!$B$31,"Согласовано","Пересмотреть")) -> Нет оценок
A60: МАИ: проекты по критерию K3 | B60: ='Настройки'!B23 -> Удобство оценки и планирования
A61: Строка предпочтительнее столбца | B61: ='Настройки'!B14 -> Детейлинг-центр | C61: ='Настройки'!B15 -> Планировщик покупок | D61: ='Настройки'!B16 -> Концепция 3 | E61: ='Настройки'!B17 -> Концепция 4
A62: ='Настройки'!B14 -> Детейлинг-центр | B62: 1
...

Sheet Эксперт 4
A2: Индивидуальные оценки эксперта 4
A4: Участник | B4: ='Настройки'!B10 -> Катаев Максим Игоревич
A5: Заполняйте только жёлтые ячейки. Не копируйте оценки других участников.
A7: TOPSIS: важность критерия | B7: Оценка 1–9
A8: ='Настройки'!B21 -> Практическая полезность
A9: ='Настройки'!B22 -> Простота реализации
A10: ='Настройки'!B23 -> Удобство оценки и планирования
A11: ='Настройки'!B24 -> Интерес команды
A13: TOPSIS: оценка проекта | B13: ='Настройки'!B21 -> Практическая полезность | C13: ='Настройки'!B22 -> Простота реализации | D13: ='Настройки'!B23 -> Удобство оценки и планирования | E13: ='Настройки'!B24 -> Интерес команды
A14: ='Настройки'!B14 -> Детейлинг-центр
A15: ='Настройки'!B15 -> Планировщик покупок
A16: ='Настройки'!B16 -> Концепция 3
A17: ='Настройки'!B17 -> Концепция 4
A19: Оценок TOPSIS заполнено / 20 | B19: =COUNT(B8:B11,B14:E17) -> 0
A21: МАИ: 1 равноценно; 3 умеренно; 5 сильно; 7 очень сильно; 9 предельно.
A22: Если строка уступает столбцу, вводите =1/3, =1/5 и т. п.
A24: МАИ: сравнение важности критериев
A25: Строка предпочтительнее столбца | B25: ='Настройки'!B21 -> Практическая полезность | C25: ='Настройки'!B22 -> Простота реализации | D25: ='Настройки'!B23 -> Удобство оценки и планирования | E25: ='Настройки'!B24 -> Интерес команды
A26: ='Настройки'!B21 -> Практическая полезность | B26: 1
A27: ='Настройки'!B22 -> Простота реализации | B27: =IF(COUNT(C26)=0,"",1/C26) | C27: 1
A28: ='Настройки'!B23 -> Удобство оценки и планирования | B28: =IF(COUNT(D26)=0,"",1/D26) | C28: =IF(COUNT(D27)=0,"",1/D27) | D28: 1
A29: ='Настройки'!B24 -> Интерес команды | B29: =IF(COUNT(E26)=0,"",1/E26) | C29: =IF(COUNT(E27)=0,"",1/E27) | D29: =IF(COUNT(E28)=0,"",1/E28) | E29: 1
A31: CR: допустимо не более 0,10 | B31: =IF(COUNT('МАИ'!B308)=0,"",'МАИ'!B308) | C31: =IF(COUNT(B31)=0,"Нет оценок",IF(B31<='Настройки'!$B$31,"Согласовано","Пересмотреть")) -> Нет оценок
A36: МАИ: проекты по критерию K1 | B36: ='Настройки'!B21 -> Практическая полезность
A37: Строка предпочтительнее столбца | B37: ='Настройки'!B14 -> Детейлинг-центр | C37: ='Настройки'!B15 -> Планировщик покупок | D37: ='Настройки'!B16 -> Концепция 3 | E37: ='Настройки'!B17 -> Концепция 4
A38: ='Настройки'!B14 -> Детейлинг-центр | B38: 1
A39: ='Настройки'!B15 -> Планировщик покупок | B39: =IF(COUNT(C38)=0,"",1/C38) | C39: 1
A40: ='Настройки'!B16 -> Концепция 3 | B40: =IF(COUNT(D38)=0,"",1/D38) | C40: =IF(COUNT(D39)=0,"",1/D39) | D40: 1
A41: ='Настройки'!B17 -> Концепция 4 | B41: =IF(COUNT(E38)=0,"",1/E38) | C41: =IF(COUNT(E39)=0,"",1/E39) | D41: =IF(COUNT(E40)=0,"",1/E40) | E41: 1
A43: CR: допустимо не более 0,10 | B43: =IF(COUNT('МАИ'!B322)=0,"",'МАИ'!B322) | C43: =IF(COUNT(B43)=0,"Нет оценок",IF(B43<='Настройки'!$B$31,"Согласовано","Пересмотреть")) -> Нет оценок
A48: МАИ: проекты по критерию K2 | B48: ='Настройки'!B22 -> Простота реализации
A49: Строка предпочтительнее столбца | B49: ='Настройки'!B14 -> Детейлинг-центр | C49: ='Настройки'!B15 -> Планировщик покупок | D49: ='Настройки'!B16 -> Концепция 3 | E49: ='Настройки'!B17 -> Концепция 4
A50: ='Настройки'!B14 -> Детейлинг-центр | B50: 1
A51: ='Настройки'!B15 -> Планировщик покупок | B51: =IF(COUNT(C50)=0,"",1/C50) | C51: 1
A52: ='Настройки'!B16 -> Концепция 3 | B52: =IF(COUNT(D50)=0,"",1/D50) | C52: =IF(COUNT(D51)=0,"",1/D51) | D52: 1
A53: ='Настройки'!B17 -> Концепция 4 | B53: =IF(COUNT(E50)=0,"",1/E50) | C53: =IF(COUNT(E51)=0,"",1/E51) | D53: =IF(COUNT(E52)=0,"",1/E52) | E53: 1
A55: CR: допустимо не более 0,10 | B55: =IF(COUNT('МАИ'!B336)=0,"",'МАИ'!B336) | C55: =IF(COUNT(B55)=0,"Нет оценок",IF(B55<='Настройки'!$B$31,"Согласовано","Пересмотреть")) -> Нет оценок
A60: МАИ: проекты по критерию K3 | B60: ='Настройки'!B23 -> Удобство оценки и планирования
A61: Строка предпочтительнее столбца | B61: ='Настройки'!B14 -> Детейлинг-центр | C61: ='Настройки'!B15 -> Планировщик покупок | D61: ='Настройки'!B16 -> Концепция 3 | E61: ='Настройки'!B17 -> Концепция 4
A62: ='Настройки'!B14 -> Детейлинг-центр | B62: 1
...

Sheet TOPSIS
A2: Нечёткий коллективный TOPSIS
A4: Заполнено оценок / 80 | B4: ='Эксперт 1'!B19+'Эксперт 2'!B19+'Эксперт 3'!B19+'Эксперт 4'!B19 -> 4
A6: Критерий | B6: Направление | C6: L | D6: M | E6: U | F6: Вес L | G6: Вес M | H6: Вес U
A7: ='Настройки'!B21 -> Практическая полезность | B7: ='Настройки'!C21 -> MAX | C7: =IF(COUNT('Эксперт 1'!B8,'Эксперт 2'!B8,'Эксперт 3'!B8,'Эксперт 4'!B8)<4,"",MIN('Эксперт 1'!B8,'Эксперт 2'!B8,'Эксперт 3'!B8,'Эксперт 4'!B8)) | D7: =IF(COUNT('Эксперт 1'!B8,'Эксперт 2'!B8,'Эксперт 3'!B8,'Эксперт 4'!B8)<4,"",MEDIAN('Эксперт 1'!B8,'Эксперт 2'!B8,'Эксперт 3'!B8,'Эксперт 4'!B8)) | E7: =IF(COUNT('Эксперт 1'!B8,'Эксперт 2'!B8,'Эксперт 3'!B8,'Эксперт 4'!B8)<4,"",MAX('Эксперт 1'!B8,'Эксперт 2'!B8,'Эксперт 3'!B8,'Эксперт 4'!B8)) | F7: =IF(C7="","",C7/'Настройки'!$B$30) | G7: =IF(D7="","",D7/'Настройки'!$B$30) | H7: =IF(E7="","",E7/'Настройки'!$B$30)
A8: ='Настройки'!B22 -> Простота реализации | B8: ='Настройки'!C22 -> MAX | C8: =IF(COUNT('Эксперт 1'!B9,'Эксперт 2'!B9,'Эксперт 3'!B9,'Эксперт 4'!B9)<4,"",MIN('Эксперт 1'!B9,'Эксперт 2'!B9,'Эксперт 3'!B9,'Эксперт 4'!B9)) | D8: =IF(COUNT('Эксперт 1'!B9,'Эксперт 2'!B9,'Эксперт 3'!B9,'Эксперт 4'!B9)<4,"",MEDIAN('Эксперт 1'!B9,'Эксперт 2'!B9,'Эксперт 3'!B9,'Эксперт 4'!B9)) | E8: =IF(COUNT('Эксперт 1'!B9,'Эксперт 2'!B9,'Эксперт 3'!B9,'Эксперт 4'!B9)<4,"",MAX('Эксперт 1'!B9,'Эксперт 2'!B9,'Эксперт 3'!B9,'Эксперт 4'!B9)) | F8: =IF(C8="","",C8/'Настройки'!$B$30) | G8: =IF(D8="","",D8/'Настройки'!$B$30) | H8: =IF(E8="","",E8/'Настройки'!$B$30)
A9: ='Настройки'!B23 -> Удобство оценки и планирования | B9: ='Настройки'!C23 -> MAX | C9: =IF(COUNT('Эксперт 1'!B10,'Эксперт 2'!B10,'Эксперт 3'!B10,'Эксперт 4'!B10)<4,"",MIN('Эксперт 1'!B10,'Эксперт 2'!B10,'Эксперт 3'!B10,'Эксперт 4'!B10)) | D9: =IF(COUNT('Эксперт 1'!B10,'Эксперт 2'!B10,'Эксперт 3'!B10,'Эксперт 4'!B10)<4,"",MEDIAN('Эксперт 1'!B10,'Эксперт 2'!B10,'Эксперт 3'!B10,'Эксперт 4'!B10)) | E9: =IF(COUNT('Эксперт 1'!B10,'Эксперт 2'!B10,'Эксперт 3'!B10,'Эксперт 4'!B10)<4,"",MAX('Эксперт 1'!B10,'Эксперт 2'!B10,'Эксперт 3'!B10,'Эксперт 4'!B10)) | F9: =IF(C9="","",C9/'Настройки'!$B$30) | G9: =IF(D9="","",D9/'Настройки'!$B$30) | H9: =IF(E9="","",E9/'Настройки'!$B$30)
A10: ='Настройки'!B24 -> Интерес команды | B10: ='Настройки'!C24 -> MAX | C10: =IF(COUNT('Эксперт 1'!B11,'Эксперт 2'!B11,'Эксперт 3'!B11,'Эксперт 4'!B11)<4,"",MIN('Эксперт 1'!B11,'Эксперт 2'!B11,'Эксперт 3'!B11,'Эксперт 4'!B11)) | D10: =IF(COUNT('Эксперт 1'!B11,'Эксперт 2'!B11,'Эксперт 3'!B11,'Эксперт 4'!B11)<4,"",MEDIAN('Эксперт 1'!B11,'Эксперт 2'!B11,'Эксперт 3'!B11,'Эксперт 4'!B11)) | E10: =IF(COUNT('Эксперт 1'!B11,'Эксперт 2'!B11,'Эксперт 3'!B11,'Эксперт 4'!B11)<4,"",MAX('Эксперт 1'!B11,'Эксперт 2'!B11,'Эксперт 3'!B11,'Эксперт 4'!B11)) | F10: =IF(C10="","",C10/'Настройки'!$B$30) | G10: =IF(D10="","",D10/'Настройки'!$B$30) | H10: =IF(E10="","",E10/'Настройки'!$B$30)
A14: Проект | B14: Критерий | C14: L | D14: M | E14: U | F14: Норм. L | G14: Норм. M | H14: Норм. U | I14: Взв. L | J14: Взв. M | K14: Взв. U | L14: d+ | M14: d−
A15: ='Настройки'!B14 -> Детейлинг-центр | B15: ='Настройки'!B21 -> Практическая полезность | C15: =IF(COUNT('Эксперт 1'!B14,'Эксперт 2'!B14,'Эксперт 3'!B14,'Эксперт 4'!B14)<4,"",MIN('Эксперт 1'!B14,'Эксперт 2'!B14,'Эксперт 3'!B14,'Эксперт 4'!B14)) | D15: =IF(COUNT('Эксперт 1'!B14,'Эксперт 2'!B14,'Эксперт 3'!B14,'Эксперт 4'!B14)<4,"",MEDIAN('Эксперт 1'!B14,'Эксперт 2'!B14,'Эксперт 3'!B14,'Эксперт 4'!B14)) | E15: =IF(COUNT('Эксперт 1'!B14,'Эксперт 2'!B14,'Эксперт 3'!B14,'Эксперт 4'!B14)<4,"",MAX('Эксперт 1'!B14,'Эксперт 2'!B14,'Эксперт 3'!B14,'Эксперт 4'!B14)) | F15: =IF($B$4<80,"",IF($B$7="MAX",C15/MAX(E15,E19,E23,E27),MIN(C15,C19,C23,C27)/E15)) | G15: =IF($B$4<80,"",IF($B$7="MAX",D15/MAX(E15,E19,E23,E27),MIN(C15,C19,C23,C27)/D15)) | H15: =IF($B$4<80,"",IF($B$7="MAX",E15/MAX(E15,E19,E23,E27),MIN(C15,C19,C23,C27)/C15)) | I15: =IF(F15="","",F15*F7) | J15: =IF(G15="","",G15*G7) | K15: =IF(H15="","",H15*H7) | L15: =IF(I15="","",SQRT(((I15-1)^2+(J15-1)^2+(K15-1)^2)/3)) | M15: =IF(I15="","",SQRT((I15^2+J15^2+K15^2)/3))
A16: ='Настройки'!B14 -> Детейлинг-центр | B16: ='Настройки'!B22 -> Простота реализации | C16: =IF(COUNT('Эксперт 1'!C14,'Эксперт 2'!C14,'Эксперт 3'!C14,'Эксперт 4'!C14)<4,"",MIN('Эксперт 1'!C14,'Эксперт 2'!C14,'Эксперт 3'!C14,'Эксперт 4'!C14)) | D16: =IF(COUNT('Эксперт 1'!C14,'Эксперт 2'!C14,'Эксперт 3'!C14,'Эксперт 4'!C14)<4,"",MEDIAN('Эксперт 1'!C14,'Эксперт 2'!C14,'Эксперт 3'!C14,'Эксперт 4'!C14)) | E16: =IF(COUNT('Эксперт 1'!C14,'Эксперт 2'!C14,'Эксперт 3'!C14,'Эксперт 4'!C14)<4,"",MAX('Эксперт 1'!C14,'Эксперт 2'!C14,'Эксперт 3'!C14,'Эксперт 4'!C14)) | F16: =IF($B$4<80,"",IF($B$8="MAX",C16/MAX(E16,E20,E24,E28),MIN(C16,C20,C24,C28)/E16)) | G16: =IF($B$4<80,"",IF($B$8="MAX",D16/MAX(E16,E20,E24,E28),MIN(C16,C20,C24,C28)/D16)) | H16: =IF($B$4<80,"",IF($B$8="MAX",E16/MAX(E16,E20,E24,E28),MIN(C16,C20,C24,C28)/C16)) | I16: =IF(F16="","",F16*F8) | J16: =IF(G16="","",G16*G8) | K16: =IF(H16="","",H16*H8) | L16: =IF(I16="","",SQRT(((I16-1)^2+(J16-1)^2+(K16-1)^2)/3)) | M16: =IF(I16="","",SQRT((I16^2+J16^2+K16^2)/3))
A17: ='Настройки'!B14 -> Детейлинг-центр | B17: ='Настройки'!B23 -> Удобство оценки и планирования | C17: =IF(COUNT('Эксперт 1'!D14,'Эксперт 2'!D14,'Эксперт 3'!D14,'Эксперт 4'!D14)<4,"",MIN('Эксперт 1'!D14,'Эксперт 2'!D14,'Эксперт 3'!D14,'Эксперт 4'!D14)) | D17: =IF(COUNT('Эксперт 1'!D14,'Эксперт 2'!D14,'Эксперт 3'!D14,'Эксперт 4'!D14)<4,"",MEDIAN('Эксперт 1'!D14,'Эксперт 2'!D14,'Эксперт 3'!D14,'Эксперт 4'!D14)) | E17: =IF(COUNT('Эксперт 1'!D14,'Эксперт 2'!D14,'Эксперт 3'!D14,'Эксперт 4'!D14)<4,"",MAX('Эксперт 1'!D14,'Эксперт 2'!D14,'Эксперт 3'!D14,'Эксперт 4'!D14)) | F17: =IF($B$4<80,"",IF($B$9="MAX",C17/MAX(E17,E21,E25,E29),MIN(C17,C21,C25,C29)/E17)) | G17: =IF($B$4<80,"",IF($B$9="MAX",D17/MAX(E17,E21,E25,E29),MIN(C17,C21,C25,C29)/D17)) | H17: =IF($B$4<80,"",IF($B$9="MAX",E17/MAX(E17,E21,E25,E29),MIN(C17,C21,C25,C29)/C17)) | I17: =IF(F17="","",F17*F9) | J17: =IF(G17="","",G17*G9) | K17: =IF(H17="","",H17*H9) | L17: =IF(I17="","",SQRT(((I17-1)^2+(J17-1)^2+(K17-1)^2)/3)) | M17: =IF(I17="","",SQRT((I17^2+J17^2+K17^2)/3))
A18: ='Настройки'!B14 -> Детейлинг-центр | B18: ='Настройки'!B24 -> Интерес команды | C18: =IF(COUNT('Эксперт 1'!E14,'Эксперт 2'!E14,'Эксперт 3'!E14,'Эксперт 4'!E14)<4,"",MIN('Эксперт 1'!E14,'Эксперт 2'!E14,'Эксперт 3'!E14,'Эксперт 4'!E14)) | D18: =IF(COUNT('Эксперт 1'!E14,'Эксперт 2'!E14,'Эксперт 3'!E14,'Эксперт 4'!E14)<4,"",MEDIAN('Эксперт 1'!E14,'Эксперт 2'!E14,'Эксперт 3'!E14,'Эксперт 4'!E14)) | E18: =IF(COUNT('Эксперт 1'!E14,'Эксперт 2'!E14,'Эксперт 3'!E14,'Эксперт 4'!E14)<4,"",MAX('Эксперт 1'!E14,'Эксперт 2'!E14,'Эксперт 3'!E14,'Эксперт 4'!E14)) | F18: =IF($B$4<80,"",IF($B$10="MAX",C18/MAX(E18,E22,E26,E30),MIN(C18,C22,C26,C30)/E18)) | G18: =IF($B$4<80,"",IF($B$10="MAX",D18/MAX(E18,E22,E26,E30),MIN(C18,C22,C26,C30)/D18)) | H18: =IF($B$4<80,"",IF($B$10="MAX",E18/MAX(E18,E22,E26,E30),MIN(C18,C22,C26,C30)/C18)) | I18: =IF(F18="","",F18*F10) | J18: =IF(G18="","",G18*G10) | K18: =IF(H18="","",H18*H10) | L18: =IF(I18="","",SQRT(((I18-1)^2+(J18-1)^2+(K18-1)^2)/3)) | M18: =IF(I18="","",SQRT((I18^2+J18^2+K18^2)/3))
A19: ='Настройки'!B15 -> Планировщик покупок | B19: ='Настройки'!B21 -> Практическая полезность | C19: =IF(COUNT('Эксперт 1'!B15,'Эксперт 2'!B15,'Эксперт 3'!B15,'Эксперт 4'!B15)<4,"",MIN('Эксперт 1'!B15,'Эксперт 2'!B15,'Эксперт 3'!B15,'Эксперт 4'!B15)) | D19: =IF(COUNT('Эксперт 1'!B15,'Эксперт 2'!B15,'Эксперт 3'!B15,'Эксперт 4'!B15)<4,"",MEDIAN('Эксперт 1'!B15,'Эксперт 2'!B15,'Эксперт 3'!B15,'Эксперт 4'!B15)) | E19: =IF(COUNT('Эксперт 1'!B15,'Эксперт 2'!B15,'Эксперт 3'!B15,'Эксперт 4'!B15)<4,"",MAX('Эксперт 1'!B15,'Эксперт 2'!B15,'Эксперт 3'!B15,'Эксперт 4'!B15)) | F19: =IF($B$4<80,"",IF($B$7="MAX",C19/MAX(E15,E19,E23,E27),MIN(C15,C19,C23,C27)/E19)) | G19: =IF($B$4<80,"",IF($B$7="MAX",D19/MAX(E15,E19,E23,E27),MIN(C15,C19,C23,C27)/D19)) | H19: =IF($B$4<80,"",IF($B$7="MAX",E19/MAX(E15,E19,E23,E27),MIN(C15,C19,C23,C27)/C19)) | I19: =IF(F19="","",F19*F7) | J19: =IF(G19="","",G19*G7) | K19: =IF(H19="","",H19*H7) | L19: =IF(I19="","",SQRT(((I19-1)^2+(J19-1)^2+(K19-1)^2)/3)) | M19: =IF(I19="","",SQRT((I19^2+J19^2+K19^2)/3))
A20: ='Настройки'!B15 -> Планировщик покупок | B20: ='Настройки'!B22 -> Простота реализации | C20: =IF(COUNT('Эксперт 1'!C15,'Эксперт 2'!C15,'Эксперт 3'!C15,'Эксперт 4'!C15)<4,"",MIN('Эксперт 1'!C15,'Эксперт 2'!C15,'Эксперт 3'!C15,'Эксперт 4'!C15)) | D20: =IF(COUNT('Эксперт 1'!C15,'Эксперт 2'!C15,'Эксперт 3'!C15,'Эксперт 4'!C15)<4,"",MEDIAN('Эксперт 1'!C15,'Эксперт 2'!C15,'Эксперт 3'!C15,'Эксперт 4'!C15)) | E20: =IF(COUNT('Эксперт 1'!C15,'Эксперт 2'!C15,'Эксперт 3'!C15,'Эксперт 4'!C15)<4,"",MAX('Эксперт 1'!C15,'Эксперт 2'!C15,'Эксперт 3'!C15,'Эксперт 4'!C15)) | F20: =IF($B$4<80,"",IF($B$8="MAX",C20/MAX(E16,E20,E24,E28),MIN(C16,C20,C24,C28)/E20)) | G20: =IF($B$4<80,"",IF($B$8="MAX",D20/MAX(E16,E20,E24,E28),MIN(C16,C20,C24,C28)/D20)) | H20: =IF($B$4<80,"",IF($B$8="MAX",E20/MAX(E16,E20,E24,E28),MIN(C16,C20,C24,C28)/C20)) | I20: =IF(F20="","",F20*F8) | J20: =IF(G20="","",G20*G8) | K20: =IF(H20="","",H20*H8) | L20: =IF(I20="","",SQRT(((I20-1)^2+(J20-1)^2+(K20-1)^2)/3)) | M20: =IF(I20="","",SQRT((I20^2+J20^2+K20^2)/3))
A21: ='Настройки'!B15 -> Планировщик покупок | B21: ='Настройки'!B23 -> Удобство оценки и планирования | C21: =IF(COUNT('Эксперт 1'!D15,'Эксперт 2'!D15,'Эксперт 3'!D15,'Эксперт 4'!D15)<4,"",MIN('Эксперт 1'!D15,'Эксперт 2'!D15,'Эксперт 3'!D15,'Эксперт 4'!D15)) | D21: =IF(COUNT('Эксперт 1'!D15,'Эксперт 2'!D15,'Эксперт 3'!D15,'Эксперт 4'!D15)<4,"",MEDIAN('Эксперт 1'!D15,'Эксперт 2'!D15,'Эксперт 3'!D15,'Эксперт 4'!D15)) | E21: =IF(COUNT('Эксперт 1'!D15,'Эксперт 2'!D15,'Эксперт 3'!D15,'Эксперт 4'!D15)<4,"",MAX('Эксперт 1'!D15,'Эксперт 2'!D15,'Эксперт 3'!D15,'Эксперт 4'!D15)) | F21: =IF($B$4<80,"",IF($B$9="MAX",C21/MAX(E17,E21,E25,E29),MIN(C17,C21,C25,C29)/E21)) | G21: =IF($B$4<80,"",IF($B$9="MAX",D21/MAX(E17,E21,E25,E29),MIN(C17,C21,C25,C29)/D21)) | H21: =IF($B$4<80,"",IF($B$9="MAX",E21/MAX(E17,E21,E25,E29),MIN(C17,C21,C25,C29)/C21)) | I21: =IF(F21="","",F21*F9) | J21: =IF(G21="","",G21*G9) | K21: =IF(H21="","",H21*H9) | L21: =IF(I21="","",SQRT(((I21-1)^2+(J21-1)^2+(K21-1)^2)/3)) | M21: =IF(I21="","",SQRT((I21^2+J21^2+K21^2)/3))
A22: ='Настройки'!B15 -> Планировщик покупок | B22: ='Настройки'!B24 -> Интерес команды | C22: =IF(COUNT('Эксперт 1'!E15,'Эксперт 2'!E15,'Эксперт 3'!E15,'Эксперт 4'!E15)<4,"",MIN('Эксперт 1'!E15,'Эксперт 2'!E15,'Эксперт 3'!E15,'Эксперт 4'!E15)) | D22: =IF(COUNT('Эксперт 1'!E15,'Эксперт 2'!E15,'Эксперт 3'!E15,'Эксперт 4'!E15)<4,"",MEDIAN('Эксперт 1'!E15,'Эксперт 2'!E15,'Эксперт 3'!E15,'Эксперт 4'!E15)) | E22: =IF(COUNT('Эксперт 1'!E15,'Эксперт 2'!E15,'Эксперт 3'!E15,'Эксперт 4'!E15)<4,"",MAX('Эксперт 1'!E15,'Эксперт 2'!E15,'Эксперт 3'!E15,'Эксперт 4'!E15)) | F22: =IF($B$4<80,"",IF($B$10="MAX",C22/MAX(E18,E22,E26,E30),MIN(C18,C22,C26,C30)/E22)) | G22: =IF($B$4<80,"",IF($B$10="MAX",D22/MAX(E18,E22,E26,E30),MIN(C18,C22,C26,C30)/D22)) | H22: =IF($B$4<80,"",IF($B$10="MAX",E22/MAX(E18,E22,E26,E30),MIN(C18,C22,C26,C30)/C22)) | I22: =IF(F22="","",F22*F10) | J22: =IF(G22="","",G22*G10) | K22: =IF(H22="","",H22*H10) | L22: =IF(I22="","",SQRT(((I22-1)^2+(J22-1)^2+(K22-1)^2)/3)) | M22: =IF(I22="","",SQRT((I22^2+J22^2+K22^2)/3))
A23: ='Настройки'!B16 -> Концепция 3 | B23: ='Настройки'!B21 -> Практическая полезность | C23: =IF(COUNT('Эксперт 1'!B16,'Эксперт 2'!B16,'Эксперт 3'!B16,'Эксперт 4'!B16)<4,"",MIN('Эксперт 1'!B16,'Эксперт 2'!B16,'Эксперт 3'!B16,'Эксперт 4'!B16)) | D23: =IF(COUNT('Эксперт 1'!B16,'Эксперт 2'!B16,'Эксперт 3'!B16,'Эксперт 4'!B16)<4,"",MEDIAN('Эксперт 1'!B16,'Эксперт 2'!B16,'Эксперт 3'!B16,'Эксперт 4'!B16)) | E23: =IF(COUNT('Эксперт 1'!B16,'Эксперт 2'!B16,'Эксперт 3'!B16,'Эксперт 4'!B16)<4,"",MAX('Эксперт 1'!B16,'Эксперт 2'!B16,'Эксперт 3'!B16,'Эксперт 4'!B16)) | F23: =IF($B$4<80,"",IF($B$7="MAX",C23/MAX(E15,E19,E23,E27),MIN(C15,C19,C23,C27)/E23)) | G23: =IF($B$4<80,"",IF($B$7="MAX",D23/MAX(E15,E19,E23,E27),MIN(C15,C19,C23,C27)/D23)) | H23: =IF($B$4<80,"",IF($B$7="MAX",E23/MAX(E15,E19,E23,E27),MIN(C15,C19,C23,C27)/C23)) | I23: =IF(F23="","",F23*F7) | J23: =IF(G23="","",G23*G7) | K23: =IF(H23="","",H23*H7) | L23: =IF(I23="","",SQRT(((I23-1)^2+(J23-1)^2+(K23-1)^2)/3)) | M23: =IF(I23="","",SQRT((I23^2+J23^2+K23^2)/3))
A24: ='Настройки'!B16 -> Концепция 3 | B24: ='Настройки'!B22 -> Простота реализации | C24: =IF(COUNT('Эксперт 1'!C16,'Эксперт 2'!C16,'Эксперт 3'!C16,'Эксперт 4'!C16)<4,"",MIN('Эксперт 1'!C16,'Эксперт 2'!C16,'Эксперт 3'!C16,'Эксперт 4'!C16)) | D24: =IF(COUNT('Эксперт 1'!C16,'Эксперт 2'!C16,'Эксперт 3'!C16,'Эксперт 4'!C16)<4,"",MEDIAN('Эксперт 1'!C16,'Эксперт 2'!C16,'Эксперт 3'!C16,'Эксперт 4'!C16)) | E24: =IF(COUNT('Эксперт 1'!C16,'Эксперт 2'!C16,'Эксперт 3'!C16,'Эксперт 4'!C16)<4,"",MAX('Эксперт 1'!C16,'Эксперт 2'!C16,'Эксперт 3'!C16,'Эксперт 4'!C16)) | F24: =IF($B$4<80,"",IF($B$8="MAX",C24/MAX(E16,E20,E24,E28),MIN(C16,C20,C24,C28)/E24)) | G24: =IF($B$4<80,"",IF($B$8="MAX",D24/MAX(E16,E20,E24,E28),MIN(C16,C20,C24,C28)/D24)) | H24: =IF($B$4<80,"",IF($B$8="MAX",E24/MAX(E16,E20,E24,E28),MIN(C16,C20,C24,C28)/C24)) | I24: =IF(F24="","",F24*F8) | J24: =IF(G24="","",G24*G8) | K24: =IF(H24="","",H24*H8) | L24: =IF(I24="","",SQRT(((I24-1)^2+(J24-1)^2+(K24-1)^2)/3)) | M24: =IF(I24="","",SQRT((I24^2+J24^2+K24^2)/3))
A25: ='Настройки'!B16 -> Концепция 3 | B25: ='Настройки'!B23 -> Удобство оценки и планирования | C25: =IF(COUNT('Эксперт 1'!D16,'Эксперт 2'!D16,'Эксперт 3'!D16,'Эксперт 4'!D16)<4,"",MIN('Эксперт 1'!D16,'Эксперт 2'!D16,'Эксперт 3'!D16,'Эксперт 4'!D16)) | D25: =IF(COUNT('Эксперт 1'!D16,'Эксперт 2'!D16,'Эксперт 3'!D16,'Эксперт 4'!D16)<4,"",MEDIAN('Эксперт 1'!D16,'Эксперт 2'!D16,'Эксперт 3'!D16,'Эксперт 4'!D16)) | E25: =IF(COUNT('Эксперт 1'!D16,'Эксперт 2'!D16,'Эксперт 3'!D16,'Эксперт 4'!D16)<4,"",MAX('Эксперт 1'!D16,'Эксперт 2'!D16,'Эксперт 3'!D16,'Эксперт 4'!D16)) | F25: =IF($B$4<80,"",IF($B$9="MAX",C25/MAX(E17,E21,E25,E29),MIN(C17,C21,C25,C29)/E25)) | G25: =IF($B$4<80,"",IF($B$9="MAX",D25/MAX(E17,E21,E25,E29),MIN(C17,C21,C25,C29)/D25)) | H25: =IF($B$4<80,"",IF($B$9="MAX",E25/MAX(E17,E21,E25,E29),MIN(C17,C21,C25,C29)/C25)) | I25: =IF(F25="","",F25*F9) | J25: =IF(G25="","",G25*G9) | K25: =IF(H25="","",H25*H9) | L25: =IF(I25="","",SQRT(((I25-1)^2+(J25-1)^2+(K25-1)^2)/3)) | M25: =IF(I25="","",SQRT((I25^2+J25^2+K25^2)/3))
A26: ='Настройки'!B16 -> Концепция 3 | B26: ='Настройки'!B24 -> Интерес команды | C26: =IF(COUNT('Эксперт 1'!E16,'Эксперт 2'!E16,'Эксперт 3'!E16,'Эксперт 4'!E16)<4,"",MIN('Эксперт 1'!E16,'Эксперт 2'!E16,'Эксперт 3'!E16,'Эксперт 4'!E16)) | D26: =IF(COUNT('Эксперт 1'!E16,'Эксперт 2'!E16,'Эксперт 3'!E16,'Эксперт 4'!E16)<4,"",MEDIAN('Эксперт 1'!E16,'Эксперт 2'!E16,'Эксперт 3'!E16,'Эксперт 4'!E16)) | E26: =IF(COUNT('Эксперт 1'!E16,'Эксперт 2'!E16,'Эксперт 3'!E16,'Эксперт 4'!E16)<4,"",MAX('Эксперт 1'!E16,'Эксперт 2'!E16,'Эксперт 3'!E16,'Эксперт 4'!E16)) | F26: =IF($B$4<80,"",IF($B$10="MAX",C26/MAX(E18,E22,E26,E30),MIN(C18,C22,C26,C30)/E26)) | G26: =IF($B$4<80,"",IF($B$10="MAX",D26/MAX(E18,E22,E26,E30),MIN(C18,C22,C26,C30)/D26)) | H26: =IF($B$4<80,"",IF($B$10="MAX",E26/MAX(E18,E22,E26,E30),MIN(C18,C22,C26,C30)/C26)) | I26: =IF(F26="","",F26*F10) | J26: =IF(G26="","",G26*G10) | K26: =IF(H26="","",H26*H10) | L26: =IF(I26="","",SQRT(((I26-1)^2+(J26-1)^2+(K26-1)^2)/3)) | M26: =IF(I26="","",SQRT((I26^2+J26^2+K26^2)/3))
A27: ='Настройки'!B17 -> Концепция 4 | B27: ='Настройки'!B21 -> Практическая полезность | C27: =IF(COUNT('Эксперт 1'!B17,'Эксперт 2'!B17,'Эксперт 3'!B17,'Эксперт 4'!B17)<4,"",MIN('Эксперт 1'!B17,'Эксперт 2'!B17,'Эксперт 3'!B17,'Эксперт 4'!B17)) | D27: =IF(COUNT('Эксперт 1'!B17,'Эксперт 2'!B17,'Эксперт 3'!B17,'Эксперт 4'!B17)<4,"",MEDIAN('Эксперт 1'!B17,'Эксперт 2'!B17,'Эксперт 3'!B17,'Эксперт 4'!B17)) | E27: =IF(COUNT('Эксперт 1'!B17,'Эксперт 2'!B17,'Эксперт 3'!B17,'Эксперт 4'!B17)<4,"",MAX('Эксперт 1'!B17,'Эксперт 2'!B17,'Эксперт 3'!B17,'Эксперт 4'!B17)) | F27: =IF($B$4<80,"",IF($B$7="MAX",C27/MAX(E15,E19,E23,E27),MIN(C15,C19,C23,C27)/E27)) | G27: =IF($B$4<80,"",IF($B$7="MAX",D27/MAX(E15,E19,E23,E27),MIN(C15,C19,C23,C27)/D27)) | H27: =IF($B$4<80,"",IF($B$7="MAX",E27/MAX(E15,E19,E23,E27),MIN(C15,C19,C23,C27)/C27)) | I27: =IF(F27="","",F27*F7) | J27: =IF(G27="","",G27*G7) | K27: =IF(H27="","",H27*H7) | L27: =IF(I27="","",SQRT(((I27-1)^2+(J27-1)^2+(K27-1)^2)/3)) | M27: =IF(I27="","",SQRT((I27^2+J27^2+K27^2)/3))
A28: ='Настройки'!B17 -> Концепция 4 | B28: ='Настройки'!B22 -> Простота реализации | C28: =IF(COUNT('Эксперт 1'!C17,'Эксперт 2'!C17,'Эксперт 3'!C17,'Эксперт 4'!C17)<4,"",MIN('Эксперт 1'!C17,'Эксперт 2'!C17,'Эксперт 3'!C17,'Эксперт 4'!C17)) | D28: =IF(COUNT('Эксперт 1'!C17,'Эксперт 2'!C17,'Эксперт 3'!C17,'Эксперт 4'!C17)<4,"",MEDIAN('Эксперт 1'!C17,'Эксперт 2'!C17,'Эксперт 3'!C17,'Эксперт 4'!C17)) | E28: =IF(COUNT('Эксперт 1'!C17,'Эксперт 2'!C17,'Эксперт 3'!C17,'Эксперт 4'!C17)<4,"",MAX('Эксперт 1'!C17,'Эксперт 2'!C17,'Эксперт 3'!C17,'Эксперт 4'!C17)) | F28: =IF($B$4<80,"",IF($B$8="MAX",C28/MAX(E16,E20,E24,E28),MIN(C16,C20,C24,C28)/E28)) | G28: =IF($B$4<80,"",IF($B$8="MAX",D28/MAX(E16,E20,E24,E28),MIN(C16,C20,C24,C28)/D28)) | H28: =IF($B$4<80,"",IF($B$8="MAX",E28/MAX(E16,E20,E24,E28),MIN(C16,C20,C24,C28)/C28)) | I28: =IF(F28="","",F28*F8) | J28: =IF(G28="","",G28*G8) | K28: =IF(H28="","",H28*H8) | L28: =IF(I28="","",SQRT(((I28-1)^2+(J28-1)^2+(K28-1)^2)/3)) | M28: =IF(I28="","",SQRT((I28^2+J28^2+K28^2)/3))
A29: ='Настройки'!B17 -> Концепция 4 | B29: ='Настройки'!B23 -> Удобство оценки и планирования | C29: =IF(COUNT('Эксперт 1'!D17,'Эксперт 2'!D17,'Эксперт 3'!D17,'Эксперт 4'!D17)<4,"",MIN('Эксперт 1'!D17,'Эксперт 2'!D17,'Эксперт 3'!D17,'Эксперт 4'!D17)) | D29: =IF(COUNT('Эксперт 1'!D17,'Эксперт 2'!D17,'Эксперт 3'!D17,'Эксперт 4'!D17)<4,"",MEDIAN('Эксперт 1'!D17,'Эксперт 2'!D17,'Эксперт 3'!D17,'Эксперт 4'!D17)) | E29: =IF(COUNT('Эксперт 1'!D17,'Эксперт 2'!D17,'Эксперт 3'!D17,'Эксперт 4'!D17)<4,"",MAX('Эксперт 1'!D17,'Эксперт 2'!D17,'Эксперт 3'!D17,'Эксперт 4'!D17)) | F29: =IF($B$4<80,"",IF($B$9="MAX",C29/MAX(E17,E21,E25,E29),MIN(C17,C21,C25,C29)/E29)) | G29: =IF($B$4<80,"",IF($B$9="MAX",D29/MAX(E17,E21,E25,E29),MIN(C17,C21,C25,C29)/D29)) | H29: =IF($B$4<80,"",IF($B$9="MAX",E29/MAX(E17,E21,E25,E29),MIN(C17,C21,C25,C29)/C29)) | I29: =IF(F29="","",F29*F9) | J29: =IF(G29="","",G29*G9) | K29: =IF(H29="","",H29*H9) | L29: =IF(I29="","",SQRT(((I29-1)^2+(J29-1)^2+(K29-1)^2)/3)) | M29: =IF(I29="","",SQRT((I29^2+J29^2+K29^2)/3))
A30: ='Настройки'!B17 -> Концепция 4 | B30: ='Настройки'!B24 -> Интерес команды | C30: =IF(COUNT('Эксперт 1'!E17,'Эксперт 2'!E17,'Эксперт 3'!E17,'Эксперт 4'!E17)<4,"",MIN('Эксперт 1'!E17,'Эксперт 2'!E17,'Эксперт 3'!E17,'Эксперт 4'!E17)) | D30: =IF(COUNT('Эксперт 1'!E17,'Эксперт 2'!E17,'Эксперт 3'!E17,'Эксперт 4'!E17)<4,"",MEDIAN('Эксперт 1'!E17,'Эксперт 2'!E17,'Эксперт 3'!E17,'Эксперт 4'!E17)) | E30: =IF(COUNT('Эксперт 1'!E17,'Эксперт 2'!E17,'Эксперт 3'!E17,'Эксперт 4'!E17)<4,"",MAX('Эксперт 1'!E17,'Эксперт 2'!E17,'Эксперт 3'!E17,'Эксперт 4'!E17)) | F30: =IF($B$4<80,"",IF($B$10="MAX",C30/MAX(E18,E22,E26,E30),MIN(C18,C22,C26,C30)/E30)) | G30: =IF($B$4<80,"",IF($B$10="MAX",D30/MAX(E18,E22,E26,E30),MIN(C18,C22,C26,C30)/D30)) | H30: =IF($B$4<80,"",IF($B$10="MAX",E30/MAX(E18,E22,E26,E30),MIN(C18,C22,C26,C30)/C30)) | I30: =IF(F30="","",F30*F10) | J30: =IF(G30="","",G30*G10) | K30: =IF(H30="","",H30*H10) | L30: =IF(I30="","",SQRT(((I30-1)^2+(J30-1)^2+(K30-1)^2)/3)) | M30: =IF(I30="","",SQRT((I30^2+J30^2+K30^2)/3))
A34: Проект | B34: D+ | C34: D− | D34: CC | E34: Место
A35: ='Настройки'!B14 -> Детейлинг-центр | B35: =IF($B$4<80,"",SUM(L15:L18)) | C35: =IF($B$4<80,"",SUM(M15:M18)) | D35: =IF(B35="","",IF(B35+C35=0,0.5,C35/(B35+C35))) | E35: =IF(D35="","",1+COUNTIFS($D$35:$D$38,">"&D35))
A36: ='Настройки'!B15 -> Планировщик покупок | B36: =IF($B$4<80,"",SUM(L19:L22)) | C36: =IF($B$4<80,"",SUM(M19:M22)) | D36: =IF(B36="","",IF(B36+C36=0,0.5,C36/(B36+C36))) | E36: =IF(D36="","",1+COUNTIFS($D$35:$D$38,">"&D36))
A37: ='Настройки'!B16 -> Концепция 3 | B37: =IF($B$4<80,"",SUM(L23:L26)) | C37: =IF($B$4<80,"",SUM(M23:M26)) | D37: =IF(B37="","",IF(B37+C37=0,0.5,C37/(B37+C37))) | E37: =IF(D37="","",1+COUNTIFS($D$35:$D$38,">"&D37))
A38: ='Настройки'!B17 -> Концепция 4 | B38: =IF($B$4<80,"",SUM(L27:L30)) | C38: =IF($B$4<80,"",SUM(M27:M30)) | D38: =IF(B38="","",IF(B38+C38=0,0.5,C38/(B38+C38))) | E38: =IF(D38="","",1+COUNTIFS($D$35:$D$38,">"&D38))
A41: L = MIN; M = MEDIAN; U = MAX четырёх индивидуальных оценок.
A43: Нормализация: MAX — (L,M,U)/max U; MIN — min L/(U,M,L).
A45: Нечёткие веса: (L,M,U)/9. Идеал (1,1,1), антиидеал (0,0,0).
A47: Расстояние между тройками: корень из среднего квадрата разностей. CC = D−/(D+ + D−).

Sheet МАИ
A2: Чёткий коллективный МАИ
A4: Попарных сравнений заполнено / 120 | B4: =COUNT('Эксперт 1'!C26,'Эксперт 1'!D26,'Эксперт 1'!E26,'Эксперт 1'!D27,'Эксперт 1'!E27,'Эксперт 1'!E28,'Эксперт 1'!C38,'Эксперт 1'!D38,'Эксперт 1'!E38,'Эксперт 1'!D39,'Эксперт 1'!E39,'Эксперт 1'!E40,'Эксперт 1'!C50,'Эксперт 1'!D50,'Эксперт 1'!E50,'Эксперт 1'!D51,'Эксперт 1'!E51,'Эксперт 1'!E52,'Эксперт 1'!C62,'Эксперт 1'!D62,'Эксперт 1'!E62,'Эксперт 1'!D63,'Эксперт 1'!E63,'Эксперт 1'!E64,'Эксперт 1'!C74,'Эксперт 1'!D74,'Эксперт 1'!E74,'Эксперт 1'!D75,'Эксперт 1'!E75,'Эксперт 1'!E76,'Эксперт 2'!C26,'Эксперт 2'!D26,'Эксперт 2'!E26,'Эксперт 2'!D27,'Эксперт 2'!E27,'Эксперт 2'!E28,'Эксперт 2'!C38,'Эксперт 2'!D38,'Эксперт 2'!E38,'Эксперт 2'!D39,'Эксперт 2'!E39,'Эксперт 2'!E40,'Эксперт 2'!C50,'Эксперт 2'!D50,'Эксперт 2'!E50,'Эксперт 2'!D51,'Эксперт 2'!E51,'Эксперт 2'!E52,'Эксперт 2'!C62,'Эксперт 2'!D62,'Эксперт 2'!E62,'Эксперт 2'!D63,'Эксперт 2'!E63,'Эксперт 2'!E64,'Эксперт 2'!C74,'Эксперт 2'!D74,'Эксперт 2'!E74,'Эксперт 2'!D75,'Эксперт 2'!E75,'Эксперт 2'!E76,'Эксперт 3'!C26,'Эксперт 3'!D26,'Эксперт 3'!E26,'Эксперт 3'!D27,'Эксперт 3'!E27,'Эксперт 3'!E28,'Эксперт 3'!C38,'Эксперт 3'!D38,'Эксперт 3'!E38,'Эксперт 3'!D39,'Эксперт 3'!E39,'Эксперт 3'!E40,'Эксперт 3'!C50,'Эксперт 3'!D50,'Эксперт 3'!E50,'Эксперт 3'!D51,'Эксперт 3'!E51,'Эксперт 3'!E52,'Эксперт 3'!C62,'Эксперт 3'!D62,'Эксперт 3'!E62,'Эксперт 3'!D63,'Эксперт 3'!E63,'Эксперт 3'!E64,'Эксперт 3'!C74,'Эксперт 3'!D74,'Эксперт 3'!E74,'Эксперт 3'!D75,'Эксперт 3'!E75,'Эксперт 3'!E76,'Эксперт 4'!C26,'Эксперт 4'!D26,'Эксперт 4'!E26,'Эксперт 4'!D27,'Эксперт 4'!E27,'Эксперт 4'!E28,'Эксперт 4'!C38,'Эксперт 4'!D38,'Эксперт 4'!E38,'Эксперт 4'!D39,'Эксперт 4'!E39,'Эксперт 4'!E40,'Эксперт 4'!C50,'Эксперт 4'!D50,'Эксперт 4'!E50,'Эксперт 4'!D51,'Эксперт 4'!E51,'Эксперт 4'!E52,'Эксперт 4'!C62,'Эксперт 4'!D62,'Эксперт 4'!E62,'Эксперт 4'!D63,'Эксперт 4'!E63,'Эксперт 4'!E64,'Эксперт 4'!C74,'Эксперт 4'!D74,'Эксперт 4'!E74,'Эксперт 4'!D75,'Эксперт 4'!E75,'Эксперт 4'!E76) -> 0
A5: Матриц с CR > 0,10 | B5: =IF(B28="",0,IF(B28>'Настройки'!$B$31,1,0))+IF(B42="",0,IF(B42>'Настройки'!$B$31,1,0))+IF(B56="",0,IF(B56>'Настройки'!$B$31,1,0))+IF(B70="",0,IF(B70>'Настройки'!$B$31,1,0))+IF(B84="",0,IF(B84>'Настройки'!$B$31,1,0))+IF(B98="",0,IF(B98>'Настройки'!$B$31,1,0))+IF(B112="",0,IF(B112>'Настройки'!$B$31,1,0))+IF(B126="",0,IF(B126>'Настройки'!$B$31,1,0))+IF(B140="",0,IF(B140>'Настройки'!$B$31,1,0))+IF(B154="",0,IF(B154>'Настройки'!$B$31,1,0))+IF(B168="",0,IF(B168>'Настройки'!$B$31,1,0))+IF(B182="",0,IF(B182>'Настройки'!$B$31,1,0))+IF(B196="",0,IF(B196>'Настройки'!$B$31,1,0))+IF(B210="",0,IF(B210>'Настройки'!$B$31,1,0))+IF(B224="",0,IF(B224>'Настройки'!$B$31,1,0))+IF(B238="",0,IF(B238>'Настройки'!$B$31,1,0))+IF(B252="",0,IF(B252>'Настройки'!$B$31,1,0))+IF(B266="",0,IF(B266>'Настройки'!$B$31,1,0))+IF(B280="",0,IF(B280>'Настройки'!$B$31,1,0))+IF(B294="",0,IF(B294>'Настройки'!$B$31,1,0))+IF(B308="",0,IF(B308>'Настройки'!$B$31,1,0))+IF(B322="",0,IF(B322>'Настройки'!$B$31,1,0))+IF(B336="",0,IF(B336>'Настройки'!$B$31,1,0))+IF(B350="",0,IF(B350>'Настройки'!$B$31,1,0))+IF(B364="",0,IF(B364>'Настройки'!$B$31,1,0)) -> 0
A8: Код | B8: Проект | C8: K1 | D8: K2 | E8: K3 | F8: K4 | G8: Приоритет | H8: Место
A9: A1 | B9: ='Настройки'!B14 -> Детейлинг-центр | C9: =IF(COUNT(F36)=0,"",F36) | D9: =IF(COUNT(F50)=0,"",F50) | E9: =IF(COUNT(F64)=0,"",F64) | F9: =IF(COUNT(F78)=0,"",F78) | G9: =IF($B$4<120,"",C9*$F$22+D9*$F$23+E9*$F$24+F9*$F$25) | H9: =IF(G9="","",1+COUNTIFS($G$9:$G$12,">"&G9))
A10: A2 | B10: ='Настройки'!B15 -> Планировщик покупок | C10: =IF(COUNT(F37)=0,"",F37) | D10: =IF(COUNT(F51)=0,"",F51) | E10: =IF(COUNT(F65)=0,"",F65) | F10: =IF(COUNT(F79)=0,"",F79) | G10: =IF($B$4<120,"",C10*$F$22+D10*$F$23+E10*$F$24+F10*$F$25) | H10: =IF(G10="","",1+COUNTIFS($G$9:$G$12,">"&G10))
A11: A3 | B11: ='Настройки'!B16 -> Концепция 3 | C11: =IF(COUNT(F38)=0,"",F38) | D11: =IF(COUNT(F52)=0,"",F52) | E11: =IF(COUNT(F66)=0,"",F66) | F11: =IF(COUNT(F80)=0,"",F80) | G11: =IF($B$4<120,"",C11*$F$22+D11*$F$23+E11*$F$24+F11*$F$25) | H11: =IF(G11="","",1+COUNTIFS($G$9:$G$12,">"&G11))
A12: A4 | B12: ='Настройки'!B17 -> Концепция 4 | C12: =IF(COUNT(F39)=0,"",F39) | D12: =IF(COUNT(F53)=0,"",F53) | E12: =IF(COUNT(F67)=0,"",F67) | F12: =IF(COUNT(F81)=0,"",F81) | G12: =IF($B$4<120,"",C12*$F$22+D12*$F$23+E12*$F$24+F12*$F$25) | H12: =IF(G12="","",1+COUNTIFS($G$9:$G$12,">"&G12))
A15: Групповые сравнения: геометрическое среднее четырёх индивидуальных суждений.
A17: Приоритеты: главный собственный вектор, 40 шагов степенного метода. Проверки ниже.
A20: Коллективная матрица — критерии
A21: Элемент | B21: ='Настройки'!B21 -> Практическая полезность | C21: ='Настройки'!B22 -> Простота реализации | D21: ='Настройки'!B23 -> Удобство оценки и планирования | E21: ='Настройки'!B24 -> Интерес команды | F21: Приоритет | G21: Aw / w
A22: ='Настройки'!B21 -> Практическая полезность | B22: =IF(COUNT('Эксперт 1'!B26,'Эксперт 2'!B26,'Эксперт 3'!B26,'Эксперт 4'!B26)<4,"",PRODUCT('Эксперт 1'!B26,'Эксперт 2'!B26,'Эксперт 3'!B26,'Эксперт 4'!B26)^(1/4)) -> 1 | C22: =IF(COUNT('Эксперт 1'!C26,'Эксперт 2'!C26,'Эксперт 3'!C26,'Эксперт 4'!C26)<4,"",PRODUCT('Эксперт 1'!C26,'Эксперт 2'!C26,'Эксперт 3'!C26,'Эксперт 4'!C26)^(1/4)) | D22: =IF(COUNT('Эксперт 1'!D26,'Эксперт 2'!D26,'Эксперт 3'!D26,'Эксперт 4'!D26)<4,"",PRODUCT('Эксперт 1'!D26,'Эксперт 2'!D26,'Эксперт 3'!D26,'Эксперт 4'!D26)^(1/4)) | E22: =IF(COUNT('Эксперт 1'!E26,'Эксперт 2'!E26,'Эксперт 3'!E26,'Эксперт 4'!E26)<4,"",PRODUCT('Эксперт 1'!E26,'Эксперт 2'!E26,'Эксперт 3'!E26,'Эксперт 4'!E26)^(1/4)) | F22: =IF(AX22="","",AX22/SUM(AX$22:AX$25)) | G22: =IF(F22="","",(B22*$F$22+C22*$F$23+D22*$F$24+E22*$F$25)/F22) | J22: =IF(COUNT($B$22:$E$25)<16,"",1/4) | K22: =IF(J22="","",($B22*J$22+$C22*J$23+$D22*J$24+$E22*J$25)/SUM(J$22:J$25)) | L22: =IF(K22="","",($B22*K$22+$C22*K$23+$D22*K$24+$E22*K$25)/SUM(K$22:K$25)) | M22: =IF(L22="","",($B22*L$22+$C22*L$23+$D22*L$24+$E22*L$25)/SUM(L$22:L$25)) | N22: =IF(M22="","",($B22*M$22+$C22*M$23+$D22*M$24+$E22*M$25)/SUM(M$22:M$25)) | O22: =IF(N22="","",($B22*N$22+$C22*N$23+$D22*N$24+$E22*N$25)/SUM(N$22:N$25)) | P22: =IF(O22="","",($B22*O$22+$C22*O$23+$D22*O$24+$E22*O$25)/SUM(O$22:O$25)) | Q22: =IF(P22="","",($B22*P$22+$C22*P$23+$D22*P$24+$E22*P$25)/SUM(P$22:P$25)) | R22: =IF(Q22="","",($B22*Q$22+$C22*Q$23+$D22*Q$24+$E22*Q$25)/SUM(Q$22:Q$25)) | ... AX22: =IF(AW22="","",($B22*AW$22+$C22*AW$23+$D22*AW$24+$E22*AW$25)/SUM(AW$22:AW$25))
A23: ='Настройки'!B22 -> Простота реализации | B23: =IF(COUNT('Эксперт 1'!B27,'Эксперт 2'!B27,'Эксперт 3'!B27,'Эксперт 4'!B27)<4,"",PRODUCT('Эксперт 1'!B27,'Эксперт 2'!B27,'Эксперт 3'!B27,'Эксперт 4'!B27)^(1/4)) | C23: =IF(COUNT('Эксперт 1'!C27,'Эксперт 2'!C27,'Эксперт 3'!C27,'Эксперт 4'!C27)<4,"",PRODUCT('Эксперт 1'!C27,'Эксперт 2'!C27,'Эксперт 3'!C27,'Эксперт 4'!C27)^(1/4)) -> 1 | D23: =IF(COUNT('Эксперт 1'!D27,'Эксперт 2'!D27,'Эксперт 3'!D27,'Эксперт 4'!D27)<4,"",PRODUCT('Эксперт 1'!D27,'Эксперт 2'!D27,'Эксперт 3'!D27,'Эксперт 4'!D27)^(1/4)) | E23: =IF(COUNT('Эксперт 1'!E27,'Эксперт 2'!E27,'Эксперт 3'!E27,'Эксперт 4'!E27)<4,"",PRODUCT('Эксперт 1'!E27,'Эксперт 2'!E27,'Эксперт 3'!E27,'Эксперт 4'!E27)^(1/4)) | F23: =IF(AX23="","",AX23/SUM(AX$22:AX$25)) | G23: =IF(F23="","",(B23*$F$22+C23*$F$23+D23*$F$24+E23*$F$25)/F23) | J23: =IF(COUNT($B$22:$E$25)<16,"",1/4) | K23: =IF(J23="","",($B23*J$22+$C23*J$23+$D23*J$24+$E23*J$25)/SUM(J$22:J$25)) | L23: =IF(K23="","",($B23*K$22+$C23*K$23+$D23*K$24+$E23*K$25)/SUM(K$22:K$25)) | M23: =IF(L23="","",($B23*L$22+$C23*L$23+$D23*L$24+$E23*L$25)/SUM(L$22:L$25)) | N23: =IF(M23="","",($B23*M$22+$C23*M$23+$D23*M$24+$E23*M$25)/SUM(M$22:M$25)) | O23: =IF(N23="","",($B23*N$22+$C23*N$23+$D23*N$24+$E23*N$25)/SUM(N$22:N$25)) | P23: =IF(O23="","",($B23*O$22+$C23*O$23+$D23*O$24+$E23*O$25)/SUM(O$22:O$25)) | Q23: =IF(P23="","",($B23*P$22+$C23*P$23+$D23*P$24+$E23*P$25)/SUM(P$22:P$25)) | R23: =IF(Q23="","",($B23*Q$22+$C23*Q$23+$D23*Q$24+$E23*Q$25)/SUM(Q$22:Q$25)) | ... AX23: =IF(AW23="","",($B23*AW$22+$C23*AW$23+$D23*AW$24+$E23*AW$25)/SUM(AW$22:AW$25))
A24: ='Настройки'!B23 -> Удобство оценки и планирования | B24: =IF(COUNT('Эксперт 1'!B28,'Эксперт 2'!B28,'Эксперт 3'!B28,'Эксперт 4'!B28)<4,"",PRODUCT('Эксперт 1'!B28,'Эксперт 2'!B28,'Эксперт 3'!B28,'Эксперт 4'!B28)^(1/4)) | C24: =IF(COUNT('Эксперт 1'!C28,'Эксперт 2'!C28,'Эксперт 3'!C28,'Эксперт 4'!C28)<4,"",PRODUCT('Эксперт 1'!C28,'Эксперт 2'!C28,'Эксперт 3'!C28,'Эксперт 4'!C28)^(1/4)) | D24: =IF(COUNT('Эксперт 1'!D28,'Эксперт 2'!D28,'Эксперт 3'!D28,'Эксперт 4'!D28)<4,"",PRODUCT('Эксперт 1'!D28,'Эксперт 2'!D28,'Эксперт 3'!D28,'Эксперт 4'!D28)^(1/4)) -> 1 | E24: =IF(COUNT('Эксперт 1'!E28,'Эксперт 2'!E28,'Эксперт 3'!E28,'Эксперт 4'!E28)<4,"",PRODUCT('Эксперт 1'!E28,'Эксперт 2'!E28,'Эксперт 3'!E28,'Эксперт 4'!E28)^(1/4)) | F24: =IF(AX24="","",AX24/SUM(AX$22:AX$25)) | G24: =IF(F24="","",(B24*$F$22+C24*$F$23+D24*$F$24+E24*$F$25)/F24) | J24: =IF(COUNT($B$22:$E$25)<16,"",1/4) | K24: =IF(J24="","",($B24*J$22+$C24*J$23+$D24*J$24+$E24*J$25)/SUM(J$22:J$25)) | L24: =IF(K24="","",($B24*K$22+$C24*K$23+$D24*K$24+$E24*K$25)/SUM(K$22:K$25)) | M24: =IF(L24="","",($B24*L$22+$C24*L$23+$D24*L$24+$E24*L$25)/SUM(L$22:L$25)) | N24: =IF(M24="","",($B24*M$22+$C24*M$23+$D24*M$24+$E24*M$25)/SUM(M$22:M$25)) | O24: =IF(N24="","",($B24*N$22+$C24*N$23+$D24*N$24+$E24*N$25)/SUM(N$22:N$25)) | P24: =IF(O24="","",($B24*O$22+$C24*O$23+$D24*O$24+$E24*O$25)/SUM(O$22:O$25)) | Q24: =IF(P24="","",($B24*P$22+$C24*P$23+$D24*P$24+$E24*P$25)/SUM(P$22:P$25)) | R24: =IF(Q24="","",($B24*Q$22+$C24*Q$23+$D24*Q$24+$E24*Q$25)/SUM(Q$22:Q$25)) | ... AX24: =IF(AW24="","",($B24*AW$22+$C24*AW$23+$D24*AW$24+$E24*AW$25)/SUM(AW$22:AW$25))
A25: ='Настройки'!B24 -> Интерес команды | B25: =IF(COUNT('Эксперт 1'!B29,'Эксперт 2'!B29,'Эксперт 3'!B29,'Эксперт 4'!B29)<4,"",PRODUCT('Эксперт 1'!B29,'Эксперт 2'!B29,'Эксперт 3'!B29,'Эксперт 4'!B29)^(1/4)) | C25: =IF(COUNT('Эксперт 1'!C29,'Эксперт 2'!C29,'Эксперт 3'!C29,'Эксперт 4'!C29)<4,"",PRODUCT('Эксперт 1'!C29,'Эксперт 2'!C29,'Эксперт 3'!C29,'Эксперт 4'!C29)^(1/4)) | D25: =IF(COUNT('Эксперт 1'!D29,'Эксперт 2'!D29,'Эксперт 3'!D29,'Эксперт 4'!D29)<4,"",PRODUCT('Эксперт 1'!D29,'Эксперт 2'!D29,'Эксперт 3'!D29,'Эксперт 4'!D29)^(1/4)) | E25: =IF(COUNT('Эксперт 1'!E29,'Эксперт 2'!E29,'Эксперт 3'!E29,'Эксперт 4'!E29)<4,"",PRODUCT('Эксперт 1'!E29,'Эксперт 2'!E29,'Эксперт 3'!E29,'Эксперт 4'!E29)^(1/4)) -> 1 | F25: =IF(AX25="","",AX25/SUM(AX$22:AX$25)) | G25: =IF(F25="","",(B25*$F$22+C25*$F$23+D25*$F$24+E25*$F$25)/F25) | J25: =IF(COUNT($B$22:$E$25)<16,"",1/4) | K25: =IF(J25="","",($B25*J$22+$C25*J$23+$D25*J$24+$E25*J$25)/SUM(J$22:J$25)) | L25: =IF(K25="","",($B25*K$22+$C25*K$23+$D25*K$24+$E25*K$25)/SUM(K$22:K$25)) | M25: =IF(L25="","",($B25*L$22+$C25*L$23+$D25*L$24+$E25*L$25)/SUM(L$22:L$25)) | N25: =IF(M25="","",($B25*M$22+$C25*M$23+$D25*M$24+$E25*M$25)/SUM(M$22:M$25)) | O25: =IF(N25="","",($B25*N$22+$C25*N$23+$D25*N$24+$E25*N$25)/SUM(N$22:N$25)) | P25: =IF(O25="","",($B25*O$22+$C25*O$23+$D25*O$24+$E25*O$25)/SUM(O$22:O$25)) | Q25: =IF(P25="","",($B25*P$22+$C25*P$23+$D25*P$24+$E25*P$25)/SUM(P$22:P$25)) | R25: =IF(Q25="","",($B25*Q$22+$C25*Q$23+$D25*Q$24+$E25*Q$25)/SUM(Q$22:Q$25)) | ... AX25: =IF(AW25="","",($B25*AW$22+$C25*AW$23+$D25*AW$24+$E25*AW$25)/SUM(AW$22:AW$25))
A27: Проверка | B27: CR | C27: CI | D27: λ max | E27: Сумма весов | F27: Остаток Aw − λw
B28: =IF(COUNT(C28)=0,"",C28/'Настройки'!$B$32) | C28: =IF(D28="","",MAX(0,(D28-4)/3)) | D28: =IF(COUNT(G22:G25)<4,"",AVERAGE(G22:G25)) | E28: =IF(D28="","",SUM(F22:F25)) | F28: =IF(D28="","",MAX(ABS((G22-$D$28)*F22),ABS((G23-$D$28)*F23),ABS((G24-$D$28)*F24),ABS((G25-$D$28)*F25)))
A30: =IF(COUNT(B28)=0,"Нет оценок",IF(F28>0.00000001,"Недостаточная сходимость",IF(B28<='Настройки'!$B$31,"Согласовано","Пересмотреть сравнения"))) -> Нет оценок
A34: Коллективная матрица — проекты по K1
A35: Элемент | B35: ='Настройки'!B14 -> Детейлинг-центр | C35: ='Настройки'!B15 -> Планировщик покупок | D35: ='Настройки'!B16 -> Концепция 3 | E35: ='Настройки'!B17 -> Концепция 4 | F35: Приоритет | G35: Aw / w
A36: ='Настройки'!B14 -> Детейлинг-центр | B36: =IF(COUNT('Эксперт 1'!B38,'Эксперт 2'!B38,'Эксперт 3'!B38,'Эксперт 4'!B38)<4,"",PRODUCT('Эксперт 1'!B38,'Эксперт 2'!B38,'Эксперт 3'!B38,'Эксперт 4'!B38)^(1/4)) -> 1 | C36: =IF(COUNT('Эксперт 1'!C38,'Эксперт 2'!C38,'Эксперт 3'!C38,'Эксперт 4'!C38)<4,"",PRODUCT('Эксперт 1'!C38,'Эксперт 2'!C38,'Эксперт 3'!C38,'Эксперт 4'!C38)^(1/4)) | D36: =IF(COUNT('Эксперт 1'!D38,'Эксперт 2'!D38,'Эксперт 3'!D38,'Эксперт 4'!D38)<4,"",PRODUCT('Эксперт 1'!D38,'Эксперт 2'!D38,'Эксперт 3'!D38,'Эксперт 4'!D38)^(1/4)) | E36: =IF(COUNT('Эксперт 1'!E38,'Эксперт 2'!E38,'Эксперт 3'!E38,'Эксперт 4'!E38)<4,"",PRODUCT('Эксперт 1'!E38,'Эксперт 2'!E38,'Эксперт 3'!E38,'Эксперт 4'!E38)^(1/4)) | F36: =IF(AX36="","",AX36/SUM(AX$36:AX$39)) | G36: =IF(F36="","",(B36*$F$36+C36*$F$37+D36*$F$38+E36*$F$39)/F36) | J36: =IF(COUNT($B$36:$E$39)<16,"",1/4) | K36: =IF(J36="","",($B36*J$36+$C36*J$37+$D36*J$38+$E36*J$39)/SUM(J$36:J$39)) | L36: =IF(K36="","",($B36*K$36+$C36*K$37+$D36*K$38+$E36*K$39)/SUM(K$36:K$39)) | M36: =IF(L36="","",($B36*L$36+$C36*L$37+$D36*L$38+$E36*L$39)/SUM(L$36:L$39)) | N36: =IF(M36="","",($B36*M$36+$C36*M$37+$D36*M$38+$E36*M$39)/SUM(M$36:M$39)) | O36: =IF(N36="","",($B36*N$36+$C36*N$37+$D36*N$38+$E36*N$39)/SUM(N$36:N$39)) | P36: =IF(O36="","",($B36*O$36+$C36*O$37+$D36*O$38+$E36*O$39)/SUM(O$36:O$39)) | Q36: =IF(P36="","",($B36*P$36+$C36*P$37+$D36*P$38+$E36*P$39)/SUM(P$36:P$39)) | R36: =IF(Q36="","",($B36*Q$36+$C36*Q$37+$D36*Q$38+$E36*Q$39)/SUM(Q$36:Q$39)) | ... AX36: =IF(AW36="","",($B36*AW$36+$C36*AW$37+$D36*AW$38+$E36*AW$39)/SUM(AW$36:AW$39))
A37: ='Настройки'!B15 -> Планировщик покупок | B37: =IF(COUNT('Эксперт 1'!B39,'Эксперт 2'!B39,'Эксперт 3'!B39,'Эксперт 4'!B39)<4,"",PRODUCT('Эксперт 1'!B39,'Эксперт 2'!B39,'Эксперт 3'!B39,'Эксперт 4'!B39)^(1/4)) | C37: =IF(COUNT('Эксперт 1'!C39,'Эксперт 2'!C39,'Эксперт 3'!C39,'Эксперт 4'!C39)<4,"",PRODUCT('Эксперт 1'!C39,'Эксперт 2'!C39,'Эксперт 3'!C39,'Эксперт 4'!C39)^(1/4)) -> 1 | D37: =IF(COUNT('Эксперт 1'!D39,'Эксперт 2'!D39,'Эксперт 3'!D39,'Эксперт 4'!D39)<4,"",PRODUCT('Эксперт 1'!D39,'Эксперт 2'!D39,'Эксперт 3'!D39,'Эксперт 4'!D39)^(1/4)) | E37: =IF(COUNT('Эксперт 1'!E39,'Эксперт 2'!E39,'Эксперт 3'!E39,'Эксперт 4'!E39)<4,"",PRODUCT('Эксперт 1'!E39,'Эксперт 2'!E39,'Эксперт 3'!E39,'Эксперт 4'!E39)^(1/4)) | F37: =IF(AX37="","",AX37/SUM(AX$36:AX$39)) | G37: =IF(F37="","",(B37*$F$36+C37*$F$37+D37*$F$38+E37*$F$39)/F37) | J37: =IF(COUNT($B$36:$E$39)<16,"",1/4) | K37: =IF(J37="","",($B37*J$36+$C37*J$37+$D37*J$38+$E37*J$39)/SUM(J$36:J$39)) | L37: =IF(K37="","",($B37*K$36+$C37*K$37+$D37*K$38+$E37*K$39)/SUM(K$36:K$39)) | M37: =IF(L37="","",($B37*L$36+$C37*L$37+$D37*L$38+$E37*L$39)/SUM(L$36:L$39)) | N37: =IF(M37="","",($B37*M$36+$C37*M$37+$D37*M$38+$E37*M$39)/SUM(M$36:M$39)) | O37: =IF(N37="","",($B37*N$36+$C37*N$37+$D37*N$38+$E37*N$39)/SUM(N$36:N$39)) | P37: =IF(O37="","",($B37*O$36+$C37*O$37+$D37*O$38+$E37*O$39)/SUM(O$36:O$39)) | Q37: =IF(P37="","",($B37*P$36+$C37*P$37+$D37*P$38+$E37*P$39)/SUM(P$36:P$39)) | R37: =IF(Q37="","",($B37*Q$36+$C37*Q$37+$D37*Q$38+$E37*Q$39)/SUM(Q$36:Q$39)) | ... AX37: =IF(AW37="","",($B37*AW$36+$C37*AW$37+$D37*AW$38+$E37*AW$39)/SUM(AW$36:AW$39))
